Workbook
Name ListaSistemas: _xlfn.ANCHORARRAY('Base de Datos'!$L$6)

Sheet Base de Datos
A2: Valor de caja | B2: 30
P4: 25.4
A5: Sistema | B5: Que se toma | C5: Grosor | D5: Alto | E5: Ancho | F5: Grosor Excel | G5: Alto Excel | H5: Ancho Excel | J5: Clave (para búsqueda) | L5: Sistemas (lista automática)
A6: Picture Window | B6: Marco | C6: =O6 -> 80.01 | F6: =+C6+$B$2 -> 110.01 | G6: =+D6+$B$2 -> 30 | H6: =+E6+$B$2 -> 30 | J6: =IF($A6="","",IF(COUNTIF($A$6:$A$103,$A6)>1,$A6&" - "&$B6,$A6)) -> Picture Window | L6: {=IFERROR(_xlfn._xlws.FILTER($J$6:$J$103,$J$6:$J$103<>""),"")} -> Picture Window | O6: =3.15*$P$4 -> 80.01
A7: Dream Window | B7: Marco | C7: =O7 -> 92.456 | F7: =+C7+$B$2 -> 122.456 | G7: =+D7+$B$2 -> 30 | H7: =+E7+$B$2 -> 30 | J7: =IF($A7="","",IF(COUNTIF($A$6:$A$103,$A7)>1,$A7&" - "&$B7,$A7)) -> Dream Window | L7: Dream Window | O7: =3.64*$P$4 -> 92.456
A8: Casement out KA | B8: Marco | C8: =O8 -> 109.22 | F8: =+C8+$B$2 -> 139.22 | G8: =+D8+$B$2 -> 30 | H8: =+E8+$B$2 -> 30 | J8: =IF($A8="","",IF(COUNTIF($A$6:$A$103,$A8)>1,$A8&" - "&$B8,$A8)) -> Casement out KA | L8: Casement out KA | O8: =4.3*$P$4 -> 109.22
A9: Tilt & Turn | B9: Marco | C9: =O9 -> 150.368 | F9: =+C9+$B$2 -> 180.368 | G9: =+D9+$B$2 -> 30 | H9: =+E9+$B$2 -> 30 | J9: =IF($A9="","",IF(COUNTIF($A$6:$A$103,$A9)>1,$A9&" - "&$B9,$A9)) -> Tilt & Turn | L9: Tilt & Turn | N9: Con cremona | O9: =5.92*$P$4 -> 150.368 | P9: Sin cremona | Q9: =4.03*$P$4 -> 102.362
A10: Horizonal Roller | B10: Marco | C10: =O10 -> 77.724 | F10: =+C10+$B$2 -> 107.724 | G10: =+D10+$B$2 -> 30 | H10: =+E10+$B$2 -> 30 | J10: =IF($A10="","",IF(COUNTIF($A$6:$A$103,$A10)>1,$A10&" - "&$B10,$A10)) -> Horizonal Roller | L10: Horizonal Roller | O10: =3.06*$P$4 -> 77.724
A11: Single Hung | B11: Marco | C11: =O11 -> 75.184 | F11: =+C11+$B$2 -> 105.184 | G11: =+D11+$B$2 -> 30 | H11: =+E11+$B$2 -> 30 | J11: =IF($A11="","",IF(COUNTIF($A$6:$A$103,$A11)>1,$A11&" - "&$B11,$A11)) -> Single Hung | L11: Single Hung | O11: =2.96*$P$4 -> 75.184
A12: Window Wall | B12: Marco | C12: =O12 -> 155.194 | F12: =+C12+$B$2 -> 185.194 | G12: =+D12+$B$2 -> 30 | H12: =+E12+$B$2 -> 30 | J12: =IF($A12="","",IF(COUNTIF($A$6:$A$103,$A12)>1,$A12&" - "&$B12,$A12)) -> Window Wall | L12: Window Wall | O12: =6.11*$P$4 -> 155.194
A13: Store Fornt | B13: Marco | C13: =O13 -> 127.0254 | F13: =+C13+$B$2 -> 157.0254 | G13: =+D13+$B$2 -> 30 | H13: =+E13+$B$2 -> 30 | J13: =IF($A13="","",IF(COUNTIF($A$6:$A$103,$A13)>1,$A13&" - "&$B13,$A13)) -> Store Fornt | L13: Store Fornt | O13: =5.001*$P$4 -> 127.0254
A14: Sliding glass | B14: Hoja fija | C14: =O14 -> 94.996 | F14: =+C14+$B$2 -> 124.996 | G14: =+D14+$B$2 -> 30 | H14: =+E14+$B$2 -> 30 | J14: =IF($A14="","",IF(COUNTIF($A$6:$A$103,$A14)>1,$A14&" - "&$B14,$A14)) -> Sliding glass - Hoja fija | L14: Sliding glass - Hoja fija | O14: =3.74*$P$4 -> 94.996
A15: Sliding glass | B15: Hoja Activa | C15: =O15 -> 152.146 | F15: =+C15+$B$2 -> 182.146 | G15: =+D15+$B$2 -> 30 | H15: =+E15+$B$2 -> 30 | J15: =IF($A15="","",IF(COUNTIF($A$6:$A$103,$A15)>1,$A15&" - "&$B15,$A15)) -> Sliding glass - Hoja Activa | L15: Sliding glass - Hoja Activa | O15: =5.99*$P$4 -> 152.146
A16: Sliding glass | B16: Hoja que recibe | C16: =O16 -> 94.996 | F16: =+C16+$B$2 -> 124.996 | G16: =+D16+$B$2 -> 30 | H16: =+E16+$B$2 -> 30 | J16: =IF($A16="","",IF(COUNTIF($A$6:$A$103,$A16)>1,$A16&" - "&$B16,$A16)) -> Sliding glass - Hoja que recibe | L16: Sliding glass - Hoja que recibe | O16: =3.74*$P$4 -> 94.996
A17: French Door KA 1 hoja | B17: Marco | C17: =O17 -> 90.932 | F17: =+C17+$B$2 -> 120.932 | G17: =+D17+$B$2 -> 30 | H17: =+E17+$B$2 -> 30 | J17: =IF($A17="","",IF(COUNTIF($A$6:$A$103,$A17)>1,$A17&" - "&$B17,$A17)) -> French Door KA 1 hoja | L17: French Door KA 1 hoja | O17: =3.58*$P$4 -> 90.932
A18: French Door KA 2 hojas | B18: Marco | C18: =O18 -> 90.932 | F18: =+C18+$B$2 -> 120.932 | G18: =+D18+$B$2 -> 30 | H18: =+E18+$B$2 -> 30 | J18: =IF($A18="","",IF(COUNTIF($A$6:$A$103,$A18)>1,$A18&" - "&$B18,$A18)) -> French Door KA 2 hojas - Marco | L18: French Door KA 2 hojas - Marco | O18: =3.58*$P$4 -> 90.932
A19: French Door KA 2 hojas | B19: Hoja Pasiva | C19: =O19 -> 90.932 | F19: =+C19+$B$2 -> 120.932 | G19: =+D19+$B$2 -> 30 | H19: =+E19+$B$2 -> 30 | J19: =IF($A19="","",IF(COUNTIF($A$6:$A$103,$A19)>1,$A19&" - "&$B19,$A19)) -> French Door KA 2 hojas - Hoja Pasiva | L19: French Door KA 2 hojas - Hoja Pasiva | O19: =3.58*$P$4 -> 90.932
A20: Vintage 1 hoja | B20: Marco | C20: =O20 -> 155.448 | F20: =+C20+$B$2 -> 185.448 | G20: =+D20+$B$2 -> 30 | H20: =+E20+$B$2 -> 30 | J20: =IF($A20="","",IF(COUNTIF($A$6:$A$103,$A20)>1,$A20&" - "&$B20,$A20)) -> Vintage 1 hoja | L20: Vintage 1 hoja | O20: =6.12*$P$4 -> 155.448
A21: Vintage 2 hojas | B21: Marco | C21: =O21 -> 155.448 | F21: =+C21+$B$2 -> 185.448 | G21: =+D21+$B$2 -> 30 | H21: =+E21+$B$2 -> 30 | J21: =IF($A21="","",IF(COUNTIF($A$6:$A$103,$A21)>1,$A21&" - "&$B21,$A21)) -> Vintage 2 hojas - Marco | L21: Vintage 2 hojas - Marco | O21: =6.12*$P$4 -> 155.448
A22: Vintage 2 hojas | B22: Hoja Pasiva | C22: =O22 -> 160.02 | F22: =+C22+$B$2 -> 190.02 | G22: =+D22+$B$2 -> 30 | H22: =+E22+$B$2 -> 30 | J22: =IF($A22="","",IF(COUNTIF($A$6:$A$103,$A22)>1,$A22&" - "&$B22,$A22)) -> Vintage 2 hojas - Hoja Pasiva | L22: Vintage 2 hojas - Hoja Pasiva | O22: =6.3*$P$4 -> 160.02
A23: Otro | B23: desarmado | J23: =IF($A23="","",IF(COUNTIF($A$6:$A$103,$A23)>1,$A23&" - "&$B23,$A23)) -> Otro | L23: Otro
J24: =IF($A24="","",IF(COUNTIF($A$6:$A$103,$A24)>1,$A24&" - "&$B24,$A24))
J25: =IF($A25="","",IF(COUNTIF($A$6:$A$103,$A25)>1,$A25&" - "&$B25,$A25))
J26: =IF($A26="","",IF(COUNTIF($A$6:$A$103,$A26)>1,$A26&" - "&$B26,$A26))
J27: =IF($A27="","",IF(COUNTIF($A$6:$A$103,$A27)>1,$A27&" - "&$B27,$A27))
J28: =IF($A28="","",IF(COUNTIF($A$6:$A$103,$A28)>1,$A28&" - "&$B28,$A28))
J29: =IF($A29="","",IF(COUNTIF($A$6:$A$103,$A29)>1,$A29&" - "&$B29,$A29))
J30: =IF($A30="","",IF(COUNTIF($A$6:$A$103,$A30)>1,$A30&" - "&$B30,$A30))
J31: =IF($A31="","",IF(COUNTIF($A$6:$A$103,$A31)>1,$A31&" - "&$B31,$A31))
J32: =IF($A32="","",IF(COUNTIF($A$6:$A$103,$A32)>1,$A32&" - "&$B32,$A32))
J33: =IF($A33="","",IF(COUNTIF($A$6:$A$103,$A33)>1,$A33&" - "&$B33,$A33))
J34: =IF($A34="","",IF(COUNTIF($A$6:$A$103,$A34)>1,$A34&" - "&$B34,$A34))
J35: =IF($A35="","",IF(COUNTIF($A$6:$A$103,$A35)>1,$A35&" - "&$B35,$A35))
... J103: =IF($A103="","",IF(COUNTIF($A$6:$A$103,$A103)>1,$A103&" - "&$B103,$A103))

Sheet EasyCargo importación-Metri
A1: EasyCargo plantilla de la importación
A2: Grupo | B2: Descripción | C2: Piezas | D2: Longitud | E2: Anchura | F2: Altura | G2: Peso total | H2: Apilar | I2: Inclinar | J2: Rotar
D3: centímetros | G3: kilogramos | H3: Y/N | I3: Y/N | J3: Y/N
A4: KA French Door | B4: 13-003 | C4: 1 | D4: 30 | E4: 88.72 | F4: 239.24999 | G4: 10 | H4: N | I4: N
A5: KA French Door | B5: 14-B | C5: 1 | D5: 30 | E5: 111.8975 | F5: 298.94 | G5: 10
A6: KA French Door | B6: 15-S | C6: 1 | D6: 30 | E6: 111.8975 | F6: 298.94 | G6: 10
A7: KA French Door | B7: 29-C3_004 | C7: 1 | D7: 30 | E7: 78.56 | F7: 239.24999 | G7: 10
A8: KA French Door | B8: 34-C3_004.1 | C8: 1 | D8: 30 | E8: 78.56 | F8: 239.24999 | G8: 10
A9: KA French Door | B9: 4-C5_003 | C9: 1 | D9: 30 | E9: 88.72 | F9: 239.24999 | G9: 10
A10: KA French Door | B10: 9-003 | C10: 1 | D10: 30 | E10: 88.72 | F10: 239.24999 | G10: 10
A11: SGD | B11: 20-008 | C11: 1 | D11: 30 | E11: 123.055 | F11: 302.115 | G11: 10
A12: SGD | B12: 20-008 | C12: 1 | D12: 30 | E12: 123.055 | F12: 302.115 | G12: 10
A13: SGD | B13: 20-008 | C13: 1 | D13: 30 | E13: 123.055 | F13: 302.115 | G13: 10
A14: SGD | B14: 22-009 | C14: 1 | D14: 30 | E14: 91.5 | F14: 302.595 | G14: 10
A15: SGD | B15: 22-009 | C15: 1 | D15: 30 | E15: 91.5 | F15: 302.595 | G15: 10
A16: SGD | B16: 52-014 | C16: 1 | D16: 30 | E16: 91.5 | F16: 241.00001 | G16: 10
... A97: Picture window | B97: 64-B1 | C97: 1 | D97: 30 | E97: 73.66 | F97: 149.86 | G97: 10

Sheet Registro de Cuadros
A1: TABLA DE REGISTRO DE CUADROS | D1: espesor manda | F1: que ocupe la mayor medida posible o menor distanci posible cuando ocupe el producto
A2: Sistema y Grosor se toman de la hoja "Hoja1" (base de datos). Celdas azules = las llenas tú.
A3: Grupo | B3: Sistema | C3: Codigo | D3: Cuadro Real | E3: Cuadro escogido | F3: Grosor | G3: Alto | H3: Ancho | I3: Descripción | J3: Piezas | K3: Grosor Excel | L3: Alto Excel | M3: Ancho Excel | N3: Peso total
A4: 6253 - Raquel Zaki - Fab. Ventaneria | B4: Window Wall | C4: A | D4: Marcos | E4: Marcos | F4: =IF($B4="","",IFERROR(INDEX('Base de Datos'!$C$6:$C$103,MATCH($B4,'Base de Datos'!$J$6:$J$103,0)),"")) -> 155.194 | G4: 2743.2 | H4: 1028.56 | I4: =IF(AND($C4="",$D4=""),"",$C4&" - "&$D4) -> A - Marcos | J4: 1 | K4: =IF($F4="","",($F4+'Base de Datos'!$B$2)/10) -> 18.5194 | L4: =IF($G4="","",($G4+'Base de Datos'!$B$2)/10) -> 277.32 | M4: =IF($H4="","",($H4+'Base de Datos'!$B$2)/10) -> 105.856
A5: 6253 - Raquel Zaki - Fab. Ventaneria | B5: Window Wall | C5: A | D5: Marcos | E5: Marcos | F5: =IF($B5="","",IFERROR(INDEX('Base de Datos'!$C$6:$C$103,MATCH($B5,'Base de Datos'!$J$6:$J$103,0)),"")) -> 155.194 | G5: 2743.2 | H5: 1039.06 | I5: =IF(AND($C5="",$D5=""),"",$C5&" - "&$D5) -> A - Marcos | J5: 1 | K5: =IF($F5="","",($F5+'Base de Datos'!$B$2)/10) -> 18.5194 | L5: =IF($G5="","",($G5+'Base de Datos'!$B$2)/10) -> 277.32 | M5: =IF($H5="","",($H5+'Base de Datos'!$B$2)/10) -> 106.906
A6: 6253 - Raquel Zaki - Fab. Ventaneria | B6: Window Wall | C6: A | D6: Marcos | E6: Marcos | F6: =IF($B6="","",IFERROR(INDEX('Base de Datos'!$C$6:$C$103,MATCH($B6,'Base de Datos'!$J$6:$J$103,0)),"")) -> 155.194 | G6: 2743.2 | H6: 1045.76 | I6: =IF(AND($C6="",$D6=""),"",$C6&" - "&$D6) -> A - Marcos | J6: 1 | K6: =IF($F6="","",($F6+'Base de Datos'!$B$2)/10) -> 18.5194 | L6: =IF($G6="","",($G6+'Base de Datos'!$B$2)/10) -> 277.32 | M6: =IF($H6="","",($H6+'Base de Datos'!$B$2)/10) -> 107.576
A7: 6253 - Raquel Zaki - Fab. Ventaneria | B7: Window Wall | C7: A | D7: Marcos | E7: Marcos | F7: =IF($B7="","",IFERROR(INDEX('Base de Datos'!$C$6:$C$103,MATCH($B7,'Base de Datos'!$J$6:$J$103,0)),"")) -> 155.194 | G7: 2743.2 | H7: 1045.76 | I7: =IF(AND($C7="",$D7=""),"",$C7&" - "&$D7) -> A - Marcos | J7: 1 | K7: =IF($F7="","",($F7+'Base de Datos'!$B$2)/10) -> 18.5194 | L7: =IF($G7="","",($G7+'Base de Datos'!$B$2)/10) -> 277.32 | M7: =IF($H7="","",($H7+'Base de Datos'!$B$2)/10) -> 107.576
A8: 6253 - Raquel Zaki - Fab. Ventaneria | B8: Picture Window | C8: B | D8: Marcos | E8: Marcos | F8: =IF($B8="","",IFERROR(INDEX('Base de Datos'!$C$6:$C$103,MATCH($B8,'Base de Datos'!$J$6:$J$103,0)),"")) -> 80.01 | G8: 1676.4 | H8: 1016 | I8: =IF(AND($C8="",$D8=""),"",$C8&" - "&$D8) -> B - Marcos | J8: 1 | K8: =IF($F8="","",($F8+'Base de Datos'!$B$2)/10) -> 11.001 | L8: =IF($G8="","",($G8+'Base de Datos'!$B$2)/10) -> 170.64 | M8: =IF($H8="","",($H8+'Base de Datos'!$B$2)/10) -> 104.6 | O8: Hoja fija | P8: 152.5
A9: 6253 - Raquel Zaki - Fab. Ventaneria | B9: Picture Window | C9: B | D9: Marcos | E9: Marcos | F9: =IF($B9="","",IFERROR(INDEX('Base de Datos'!$C$6:$C$103,MATCH($B9,'Base de Datos'!$J$6:$J$103,0)),"")) -> 80.01 | G9: 1676.4 | H9: 1016 | I9: =IF(AND($C9="",$D9=""),"",$C9&" - "&$D9) -> B - Marcos | J9: 1 | K9: =IF($F9="","",($F9+'Base de Datos'!$B$2)/10) -> 11.001 | L9: =IF($G9="","",($G9+'Base de Datos'!$B$2)/10) -> 170.64 | M9: =IF($H9="","",($H9+'Base de Datos'!$B$2)/10) -> 104.6 | O9: Hoja Activa | P9: 152.5
A10: 6253 - Raquel Zaki - Fab. Ventaneria | B10: Picture Window | C10: B | D10: Marcos | E10: Marcos | F10: =IF($B10="","",IFERROR(INDEX('Base de Datos'!$C$6:$C$103,MATCH($B10,'Base de Datos'!$J$6:$J$103,0)),"")) -> 80.01 | G10: 1676.4 | H10: 1016 | I10: =IF(AND($C10="",$D10=""),"",$C10&" - "&$D10) -> B - Marcos | J10: 1 | K10: =IF($F10="","",($F10+'Base de Datos'!$B$2)/10) -> 11.001 | L10: =IF($G10="","",($G10+'Base de Datos'!$B$2)/10) -> 170.64 | M10: =IF($H10="","",($H10+'Base de Datos'!$B$2)/10) -> 104.6 | O10: Hoja que recibe | P10: 171.6
A11: 6253 - Raquel Zaki - Fab. Ventaneria | B11: Picture Window | C11: B | D11: Marcos | E11: Marcos | F11: =IF($B11="","",IFERROR(INDEX('Base de Datos'!$C$6:$C$103,MATCH($B11,'Base de Datos'!$J$6:$J$103,0)),"")) -> 80.01 | G11: 1676.4 | H11: 1016 | I11: =IF(AND($C11="",$D11=""),"",$C11&" - "&$D11) -> B - Marcos | J11: 1 | K11: =IF($F11="","",($F11+'Base de Datos'!$B$2)/10) -> 11.001 | L11: =IF($G11="","",($G11+'Base de Datos'!$B$2)/10) -> 170.64 | M11: =IF($H11="","",($H11+'Base de Datos'!$B$2)/10) -> 104.6
A12: 6253 - Raquel Zaki - Fab. Ventaneria | B12: Picture Window | C12: B | D12: Marcos | E12: Marcos | F12: =IF($B12="","",IFERROR(INDEX('Base de Datos'!$C$6:$C$103,MATCH($B12,'Base de Datos'!$J$6:$J$103,0)),"")) -> 80.01 | G12: 1676.4 | H12: 1016 | I12: =IF(AND($C12="",$D12=""),"",$C12&" - "&$D12) -> B - Marcos | J12: 1 | K12: =IF($F12="","",($F12+'Base de Datos'!$B$2)/10) -> 11.001 | L12: =IF($G12="","",($G12+'Base de Datos'!$B$2)/10) -> 170.64 | M12: =IF($H12="","",($H12+'Base de Datos'!$B$2)/10) -> 104.6
A13: 6253 - Raquel Zaki - Fab. Ventaneria | B13: Tilt & Turn | C13: C | D13: Marcos | E13: Marcos | F13: =IF($B13="","",IFERROR(INDEX('Base de Datos'!$C$6:$C$103,MATCH($B13,'Base de Datos'!$J$6:$J$103,0)),"")) -> 150.368 | G13: 1676.4 | H13: 1016 | I13: =IF(AND($C13="",$D13=""),"",$C13&" - "&$D13) -> C - Marcos | J13: 1 | K13: =IF($F13="","",($F13+'Base de Datos'!$B$2)/10) -> 18.0368 | L13: =IF($G13="","",($G13+'Base de Datos'!$B$2)/10) -> 170.64 | M13: =IF($H13="","",($H13+'Base de Datos'!$B$2)/10) -> 104.6
A14: 6253 - Raquel Zaki - Fab. Ventaneria | B14: Casement out KA | C14: D | D14: Marcos | E14: Marcos | F14: =IF($B14="","",IFERROR(INDEX('Base de Datos'!$C$6:$C$103,MATCH($B14,'Base de Datos'!$J$6:$J$103,0)),"")) -> 109.22 | G14: 1524 | H14: 609.6 | I14: =IF(AND($C14="",$D14=""),"",$C14&" - "&$D14) -> D - Marcos | J14: 1 | K14: =IF($F14="","",($F14+'Base de Datos'!$B$2)/10) -> 13.922 | L14: =IF($G14="","",($G14+'Base de Datos'!$B$2)/10) -> 155.4 | M14: =IF($H14="","",($H14+'Base de Datos'!$B$2)/10) -> 63.96
A15: 6253 - Raquel Zaki - Fab. Ventaneria | B15: VINTAGE | C15: D1 | D15: Marcos | E15: Marcos | F15: =IF($B15="","",IFERROR(INDEX('Base de Datos'!$C$6:$C$103,MATCH($B15,'Base de Datos'!$J$6:$J$103,0)),"")) | G15: 2743.2 | H15: 1574.8 | I15: =IF(AND($C15="",$D15=""),"",$C15&" - "&$D15) -> D1 - Marcos | J15: 1 | K15: =IF($F15="","",($F15+'Base de Datos'!$B$2)/10) | L15: =IF($G15="","",($G15+'Base de Datos'!$B$2)/10) -> 277.32 | M15: =IF($H15="","",($H15+'Base de Datos'!$B$2)/10) -> 160.48
A16: 6253 - Raquel Zaki - Fab. Ventaneria | B16: VINTAGE | C16: D1 | D16: Hojas | E16: Hojas | F16: =IF($B16="","",IFERROR(INDEX('Base de Datos'!$C$6:$C$103,MATCH($B16,'Base de Datos'!$J$6:$J$103,0)),"")) | G16: 2697.4 | H16: 749.15 | I16: =IF(AND($C16="",$D16=""),"",$C16&" - "&$D16) -> D1 - Hojas | J16: 1 | K16: =IF($F16="","",($F16+'Base de Datos'!$B$2)/10) | L16: =IF($G16="","",($G16+'Base de Datos'!$B$2)/10) -> 272.74 | M16: =IF($H16="","",($H16+'Base de Datos'!$B$2)/10) -> 77.915
A17: 6253 - Raquel Zaki - Fab. Ventaneria | B17: Sliding glass | C17: D12 | D17: Hoja fija | E17: Hoja fija | F17: 171.6 | G17: 2702.1 | H17: 1138.2 | I17: =IF(AND($C17="",$D17=""),"",$C17&" - "&$D17) -> D12 - Hoja fija | J17: 1 | K17: =IF($F17="","",($F17+'Base de Datos'!$B$2)/10) -> 20.16 | L17: =IF($G17="","",($G17+'Base de Datos'!$B$2)/10) -> 273.21 | M17: =IF($H17="","",($H17+'Base de Datos'!$B$2)/10) -> 116.82
A18: 6253 - Raquel Zaki - Fab. Ventaneria | B18: Sliding glass | C18: D12 | D18: Marcos | E18: Marcos | F18: 300 | G18: 300 | H18: 4521.2 | I18: =IF(AND($C18="",$D18=""),"",$C18&" - "&$D18) -> D12 - Marcos | J18: 1 | K18: =IF($F18="","",($F18+'Base de Datos'!$B$2)/10) -> 33 | L18: =IF($G18="","",($G18+'Base de Datos'!$B$2)/10) -> 33 | M18: =IF($H18="","",($H18+'Base de Datos'!$B$2)/10) -> 455.12
A19: 6253 - Raquel Zaki - Fab. Ventaneria | B19: Sliding glass | C19: D12 | D19: Hoja Activa | E19: Hoja Activa | F19: 152.5 | G19: 2702.1 | H19: 1130.9 | I19: =IF(AND($C19="",$D19=""),"",$C19&" - "&$D19) -> D12 - Hoja Activa | J19: 1 | K19: =IF($F19="","",($F19+'Base de Datos'!$B$2)/10) -> 18.25 | L19: =IF($G19="","",($G19+'Base de Datos'!$B$2)/10) -> 273.21 | M19: =IF($H19="","",($H19+'Base de Datos'!$B$2)/10) -> 116.09
A20: 6253 - Raquel Zaki - Fab. Ventaneria | B20: Sliding glass | C20: D12 | D20: Hojas | E20: Hojas | F20: 152.5 | G20: 2702.1 | H20: 1138.2 | I20: =IF(AND($C20="",$D20=""),"",$C20&" - "&$D20) -> D12 - Hojas | J20: 1 | K20: =IF($F20="","",($F20+'Base de Datos'!$B$2)/10) -> 18.25 | L20: =IF($G20="","",($G20+'Base de Datos'!$B$2)/10) -> 273.21 | M20: =IF($H20="","",($H20+'Base de Datos'!$B$2)/10) -> 116.82
A21: 6253 - Raquel Zaki - Fab. Ventaneria | B21: Sliding glass | C21: D12 | D21: Hojas | E21: Hojas | F21: 171.6 | G21: 2702.1 | H21: 1130.9 | I21: =IF(AND($C21="",$D21=""),"",$C21&" - "&$D21) -> D12 - Hojas | J21: 1 | K21: =IF($F21="","",($F21+'Base de Datos'!$B$2)/10) -> 20.16 | L21: =IF($G21="","",($G21+'Base de Datos'!$B$2)/10) -> 273.21 | M21: =IF($H21="","",($H21+'Base de Datos'!$B$2)/10) -> 116.09
A22: 6253 - Raquel Zaki - Fab. Ventaneria | B22: Sliding glass | C22: D3 | D22: Hojas | E22: Hojas | F22: 152.5 | G22: 2702.1 | H22: 960.4 | I22: =IF(AND($C22="",$D22=""),"",$C22&" - "&$D22) -> D3 - Hojas | J22: 1 | K22: =IF($F22="","",($F22+'Base de Datos'!$B$2)/10) -> 18.25 | L22: =IF($G22="","",($G22+'Base de Datos'!$B$2)/10) -> 273.21 | M22: =IF($H22="","",($H22+'Base de Datos'!$B$2)/10) -> 99.04
A23: 6253 - Raquel Zaki - Fab. Ventaneria | B23: Sliding glass | C23: D3 | D23: Hojas | E23: Hojas | F23: 152.5 | G23: 2702.1 | H23: 960.4 | I23: =IF(AND($C23="",$D23=""),"",$C23&" - "&$D23) -> D3 - Hojas | J23: 1 | K23: =IF($F23="","",($F23+'Base de Datos'!$B$2)/10) -> 18.25 | L23: =IF($G23="","",($G23+'Base de Datos'!$B$2)/10) -> 273.21 | M23: =IF($H23="","",($H23+'Base de Datos'!$B$2)/10) -> 99.04
A24: 6253 - Raquel Zaki - Fab. Ventaneria | B24: Sliding glass | C24: D3 | D24: Hojas | E24: Hojas | F24: 171.6 | G24: 2702.1 | H24: 953.1 | I24: =IF(AND($C24="",$D24=""),"",$C24&" - "&$D24) -> D3 - Hojas | J24: 1 | K24: =IF($F24="","",($F24+'Base de Datos'!$B$2)/10) -> 20.16 | L24: =IF($G24="","",($G24+'Base de Datos'!$B$2)/10) -> 273.21 | M24: =IF($H24="","",($H24+'Base de Datos'!$B$2)/10) -> 98.31
A25: 6253 - Raquel Zaki - Fab. Ventaneria | B25: Sliding glass | C25: D3 | D25: Hojas | E25: Hojas | F25: 171.6 | G25: 2702.1 | H25: 953.1 | I25: =IF(AND($C25="",$D25=""),"",$C25&" - "&$D25) -> D3 - Hojas | J25: 1 | K25: =IF($F25="","",($F25+'Base de Datos'!$B$2)/10) -> 20.16 | L25: =IF($G25="","",($G25+'Base de Datos'!$B$2)/10) -> 273.21 | M25: =IF($H25="","",($H25+'Base de Datos'!$B$2)/10) -> 98.31
A26: 6253 - Raquel Zaki - Fab. Ventaneria | B26: Sliding glass | C26: D3 | D26: Hojas | E26: Hojas | F26: 152.5 | G26: 2702.1 | H26: 953.1 | I26: =IF(AND($C26="",$D26=""),"",$C26&" - "&$D26) -> D3 - Hojas | J26: 1 | K26: =IF($F26="","",($F26+'Base de Datos'!$B$2)/10) -> 18.25 | L26: =IF($G26="","",($G26+'Base de Datos'!$B$2)/10) -> 273.21 | M26: =IF($H26="","",($H26+'Base de Datos'!$B$2)/10) -> 98.31
A27: 6253 - Raquel Zaki - Fab. Ventaneria | B27: Sliding glass | C27: D3 | D27: Hojas | E27: Hojas | F27: 152.5 | G27: 2702.1 | H27: 960.4 | I27: =IF(AND($C27="",$D27=""),"",$C27&" - "&$D27) -> D3 - Hojas | J27: 1 | K27: =IF($F27="","",($F27+'Base de Datos'!$B$2)/10) -> 18.25 | L27: =IF($G27="","",($G27+'Base de Datos'!$B$2)/10) -> 273.21 | M27: =IF($H27="","",($H27+'Base de Datos'!$B$2)/10) -> 99.04
A28: 6253 - Raquel Zaki - Fab. Ventaneria | B28: Sliding glass | C28: D3 | D28: Hojas | E28: Hojas | F28: 171.6 | G28: 2702.1 | H28: 960.4 | I28: =IF(AND($C28="",$D28=""),"",$C28&" - "&$D28) -> D3 - Hojas | J28: 1 | K28: =IF($F28="","",($F28+'Base de Datos'!$B$2)/10) -> 20.16 | L28: =IF($G28="","",($G28+'Base de Datos'!$B$2)/10) -> 273.21 | M28: =IF($H28="","",($H28+'Base de Datos'!$B$2)/10) -> 99.04
A29: 6253 - Raquel Zaki - Fab. Ventaneria | B29: Sliding glass | C29: D3 | D29: Hojas | E29: Hojas | F29: 171.6 | G29: 2702.1 | H29: 953.1 | I29: =IF(AND($C29="",$D29=""),"",$C29&" - "&$D29) -> D3 - Hojas | J29: 1 | K29: =IF($F29="","",($F29+'Base de Datos'!$B$2)/10) -> 20.16 | L29: =IF($G29="","",($G29+'Base de Datos'!$B$2)/10) -> 273.21 | M29: =IF($H29="","",($H29+'Base de Datos'!$B$2)/10) -> 98.31
A30: 6253 - Raquel Zaki - Fab. Ventaneria | B30: VINTAGE | C30: D4 | D30: Marcos | E30: Marcos | F30: =IF($B30="","",IFERROR(INDEX('Base de Datos'!$C$6:$C$103,MATCH($B30,'Base de Datos'!$J$6:$J$103,0)),"")) | G30: 2743.2 | H30: 1016 | I30: =IF(AND($C30="",$D30=""),"",$C30&" - "&$D30) -> D4 - Marcos | J30: 1 | K30: =IF($F30="","",($F30+'Base de Datos'!$B$2)/10) | L30: =IF($G30="","",($G30+'Base de Datos'!$B$2)/10) -> 277.32 | M30: =IF($H30="","",($H30+'Base de Datos'!$B$2)/10) -> 104.6
A31: 6253 - Raquel Zaki - Fab. Ventaneria | B31: Casement out KA | C31: E | D31: Marcos | E31: Marcos | F31: =IF($B31="","",IFERROR(INDEX('Base de Datos'!$C$6:$C$103,MATCH($B31,'Base de Datos'!$J$6:$J$103,0)),"")) -> 109.22 | G31: 1346.2 | H31: 908.05 | I31: =IF(AND($C31="",$D31=""),"",$C31&" - "&$D31) -> E - Marcos | J31: 1 | K31: =IF($F31="","",($F31+'Base de Datos'!$B$2)/10) -> 13.922 | L31: =IF($G31="","",($G31+'Base de Datos'!$B$2)/10) -> 137.62 | M31: =IF($H31="","",($H31+'Base de Datos'!$B$2)/10) -> 93.805
A32: 6253 - Raquel Zaki - Fab. Ventaneria | B32: Picture Window | C32: F | D32: Marcos | E32: Marcos | F32: =IF($B32="","",IFERROR(INDEX('Base de Datos'!$C$6:$C$103,MATCH($B32,'Base de Datos'!$J$6:$J$103,0)),"")) -> 80.01 | G32: 1346.2 | H32: 1968.5 | I32: =IF(AND($C32="",$D32=""),"",$C32&" - "&$D32) -> F - Marcos | J32: 1 | K32: =IF($F32="","",($F32+'Base de Datos'!$B$2)/10) -> 11.001 | L32: =IF($G32="","",($G32+'Base de Datos'!$B$2)/10) -> 137.62 | M32: =IF($H32="","",($H32+'Base de Datos'!$B$2)/10) -> 199.85
A33: 6253 - Raquel Zaki - Fab. Ventaneria | B33: Picture Window | C33: G | D33: Marcos | E33: Marcos | F33: =IF($B33="","",IFERROR(INDEX('Base de Datos'!$C$6:$C$103,MATCH($B33,'Base de Datos'!$J$6:$J$103,0)),"")) -> 80.01 | G33: 2108.2 | H33: 1676.4 | I33: =IF(AND($C33="",$D33=""),"",$C33&" - "&$D33) -> G - Marcos | J33: 1 | K33: =IF($F33="","",($F33+'Base de Datos'!$B$2)/10) -> 11.001 | L33: =IF($G33="","",($G33+'Base de Datos'!$B$2)/10) -> 213.82 | M33: =IF($H33="","",($H33+'Base de Datos'!$B$2)/10) -> 170.64
A34: 6253 - Raquel Zaki - Fab. Ventaneria | B34: Picture Window | C34: H | D34: Marcos | E34: Marcos | F34: =IF($B34="","",IFERROR(INDEX('Base de Datos'!$C$6:$C$103,MATCH($B34,'Base de Datos'!$J$6:$J$103,0)),"")) -> 80.01 | G34: 2108.2 | H34: 1016 | I34: =IF(AND($C34="",$D34=""),"",$C34&" - "&$D34) -> H - Marcos | J34: 1 | K34: =IF($F34="","",($F34+'Base de Datos'!$B$2)/10) -> 11.001 | L34: =IF($G34="","",($G34+'Base de Datos'!$B$2)/10) -> 213.82 | M34: =IF($H34="","",($H34+'Base de Datos'!$B$2)/10) -> 104.6
A35: 6253 - Raquel Zaki - Fab. Ventaneria | B35: Picture Window | C35: H | D35: Marcos | E35: Marcos | F35: =IF($B35="","",IFERROR(INDEX('Base de Datos'!$C$6:$C$103,MATCH($B35,'Base de Datos'!$J$6:$J$103,0)),"")) -> 80.01 | G35: 2108.2 | H35: 1016 | I35: =IF(AND($C35="",$D35=""),"",$C35&" - "&$D35) -> H - Marcos | J35: 1 | K35: =IF($F35="","",($F35+'Base de Datos'!$B$2)/10) -> 11.001 | L35: =IF($G35="","",($G35+'Base de Datos'!$B$2)/10) -> 213.82 | M35: =IF($H35="","",($H35+'Base de Datos'!$B$2)/10) -> 104.6
A36: 6253 - Raquel Zaki - Fab. Ventaneria | B36: Casement out KA | C36: J | D36: Marcos | E36: Marcos | F36: =IF($B36="","",IFERROR(INDEX('Base de Datos'!$C$6:$C$103,MATCH($B36,'Base de Datos'!$J$6:$J$103,0)),"")) -> 109.22 | G36: 1320.8 | H36: 1016 | I36: =IF(AND($C36="",$D36=""),"",$C36&" - "&$D36) -> J - Marcos | J36: 1 | K36: =IF($F36="","",($F36+'Base de Datos'!$B$2)/10) -> 13.922 | L36: =IF($G36="","",($G36+'Base de Datos'!$B$2)/10) -> 135.08 | M36: =IF($H36="","",($H36+'Base de Datos'!$B$2)/10) -> 104.6
A37: 6253 - Raquel Zaki - Fab. Ventaneria | B37: Picture Window | C37: K | D37: Marcos | E37: Marcos | F37: =IF($B37="","",IFERROR(INDEX('Base de Datos'!$C$6:$C$103,MATCH($B37,'Base de Datos'!$J$6:$J$103,0)),"")) -> 80.01 | G37: 1320.8 | H37: 1016 | I37: =IF(AND($C37="",$D37=""),"",$C37&" - "&$D37) -> K - Marcos | J37: 1 | K37: =IF($F37="","",($F37+'Base de Datos'!$B$2)/10) -> 11.001 | L37: =IF($G37="","",($G37+'Base de Datos'!$B$2)/10) -> 135.08 | M37: =IF($H37="","",($H37+'Base de Datos'!$B$2)/10) -> 104.6
A38: 6253 - Raquel Zaki - Fab. Ventaneria | B38: Picture Window | C38: K | D38: Marcos | E38: Marcos | F38: =IF($B38="","",IFERROR(INDEX('Base de Datos'!$C$6:$C$103,MATCH($B38,'Base de Datos'!$J$6:$J$103,0)),"")) -> 80.01 | G38: 1320.8 | H38: 1016 | I38: =IF(AND($C38="",$D38=""),"",$C38&" - "&$D38) -> K - Marcos | J38: 1 | K38: =IF($F38="","",($F38+'Base de Datos'!$B$2)/10) -> 11.001 | L38: =IF($G38="","",($G38+'Base de Datos'!$B$2)/10) -> 135.08 | M38: =IF($H38="","",($H38+'Base de Datos'!$B$2)/10) -> 104.6
A39: 6253 - Raquel Zaki - Fab. Ventaneria | B39: Picture Window | C39: K | D39: Marcos | E39: Marcos | F39: =IF($B39="","",IFERROR(INDEX('Base de Datos'!$C$6:$C$103,MATCH($B39,'Base de Datos'!$J$6:$J$103,0)),"")) -> 80.01 | G39: 1320.8 | H39: 1016 | I39: =IF(AND($C39="",$D39=""),"",$C39&" - "&$D39) -> K - Marcos | J39: 1 | K39: =IF($F39="","",($F39+'Base de Datos'!$B$2)/10) -> 11.001 | L39: =IF($G39="","",($G39+'Base de Datos'!$B$2)/10) -> 135.08 | M39: =IF($H39="","",($H39+'Base de Datos'!$B$2)/10) -> 104.6
A40: 6253 - Raquel Zaki - Fab. Ventaneria | B40: Picture Window | C40: K | D40: Marcos | E40: Marcos | F40: =IF($B40="","",IFERROR(INDEX('Base de Datos'!$C$6:$C$103,MATCH($B40,'Base de Datos'!$J$6:$J$103,0)),"")) -> 80.01 | G40: 1320.8 | H40: 1016 | I40: =IF(AND($C40="",$D40=""),"",$C40&" - "&$D40) -> K - Marcos | J40: 1 | K40: =IF($F40="","",($F40+'Base de Datos'!$B$2)/10) -> 11.001 | L40: =IF($G40="","",($G40+'Base de Datos'!$B$2)/10) -> 135.08 | M40: =IF($H40="","",($H40+'Base de Datos'!$B$2)/10) -> 104.6
...

Sheet Registro de Cuadros (2)
A1: TABLA DE REGISTRO DE CUADROS
A2: Sistema y Grosor se toman de la hoja "Hoja1" (base de datos). Celdas azules = las llenas tú.
A3: Grupo | B3: Sistema | C3: Codigo | D3: Cuadro Real | E3: Cuadro escogido | F3: Grosor | G3: Alto | H3: Ancho | I3: Descripción | J3: Piezas | K3: Grosor Excel | L3: Alto Excel | M3: Ancho Excel | N3: Peso total | O3: Apilar | P3: Inclinar | Q3: Rotar
A4: FIJO MODULAR 3 | B4: Picture Window | C4: 48-14 | D4: =IF($B4="","",IFERROR(INDEX('Base de Datos'!$B$6:$B$103,MATCH($B4,'Base de Datos'!$J$6:$J$103,0)),"No encontrado")) -> Marco | E4: Marcos | F4: =IF($B4="","",IFERROR(INDEX('Base de Datos'!$C$6:$C$103,MATCH($B4,'Base de Datos'!$J$6:$J$103,0)),"")) -> 80.01 | G4: 1524 | H4: 1193.8 | I4: =IF(AND($C4="",$D4=""),"",$C4&" - "&$D4) -> 48-14 - Marco | J4: 1 | K4: =IF($F4="","",($F4+'Base de Datos'!$B$2)/10) -> 11.001 | L4: =IF($G4="","",($G4+'Base de Datos'!$B$2)/10) -> 155.4 | M4: =IF($H4="","",($H4+'Base de Datos'!$B$2)/10) -> 122.38
A5: FIJO MODULAR 3 | B5: Picture Window | C5: 33-C15 | D5: =IF($B5="","",IFERROR(INDEX('Base de Datos'!$B$6:$B$103,MATCH($B5,'Base de Datos'!$J$6:$J$103,0)),"No encontrado")) -> Marco | E5: Marcos | F5: =IF($B5="","",IFERROR(INDEX('Base de Datos'!$C$6:$C$103,MATCH($B5,'Base de Datos'!$J$6:$J$103,0)),"")) -> 80.01 | G5: 1651 | H5: 596.9 | I5: =IF(AND($C5="",$D5=""),"",$C5&" - "&$D5) -> 33-C15 - Marco | J5: 1 | K5: =IF($F5="","",($F5+'Base de Datos'!$B$2)/10) -> 11.001 | L5: =IF($G5="","",($G5+'Base de Datos'!$B$2)/10) -> 168.1 | M5: =IF($H5="","",($H5+'Base de Datos'!$B$2)/10) -> 62.69
A6: KA WINDOW WALL | B6: Window Wall | C6: 24-C8 | D6: =IF($B6="","",IFERROR(INDEX('Base de Datos'!$B$6:$B$103,MATCH($B6,'Base de Datos'!$J$6:$J$103,0)),"No encontrado")) -> Marco | E6: Marcos | F6: =IF($B6="","",IFERROR(INDEX('Base de Datos'!$C$6:$C$103,MATCH($B6,'Base de Datos'!$J$6:$J$103,0)),"")) -> 155.194 | G6: 1080.5 | H6: 3035.3 | I6: =IF(AND($C6="",$D6=""),"",$C6&" - "&$D6) -> 24-C8 - Marco | J6: 1 | K6: =IF($F6="","",($F6+'Base de Datos'!$B$2)/10) -> 18.5194 | L6: =IF($G6="","",($G6+'Base de Datos'!$B$2)/10) -> 111.05 | M6: =IF($H6="","",($H6+'Base de Datos'!$B$2)/10) -> 306.53
A7: KA TILT-TURN | B7: Tilt & Turn | C7: 35-C1_A2.2 | D7: =IF($B7="","",IFERROR(INDEX('Base de Datos'!$B$6:$B$103,MATCH($B7,'Base de Datos'!$J$6:$J$103,0)),"No encontrado")) -> Marco | E7: Marcos | F7: =IF($B7="","",IFERROR(INDEX('Base de Datos'!$C$6:$C$103,MATCH($B7,'Base de Datos'!$J$6:$J$103,0)),"")) -> 150.368 | G7: 762 | H7: 2044.7 | I7: =IF(AND($C7="",$D7=""),"",$C7&" - "&$D7) -> 35-C1_A2.2 - Marco | J7: 1 | K7: =IF($F7="","",($F7+'Base de Datos'!$B$2)/10) -> 18.0368 | L7: =IF($G7="","",($G7+'Base de Datos'!$B$2)/10) -> 79.2 | M7: =IF($H7="","",($H7+'Base de Datos'!$B$2)/10) -> 207.47
A8: KA WINDOW WALL | B8: Window Wall | C8: 43-C2-C20_C2 | D8: =IF($B8="","",IFERROR(INDEX('Base de Datos'!$B$6:$B$103,MATCH($B8,'Base de Datos'!$J$6:$J$103,0)),"No encontrado")) -> Marco | E8: Marcos | F8: =IF($B8="","",IFERROR(INDEX('Base de Datos'!$C$6:$C$103,MATCH($B8,'Base de Datos'!$J$6:$J$103,0)),"")) -> 155.194 | G8: 998.662 | H8: 3047.4082 | I8: =IF(AND($C8="",$D8=""),"",$C8&" - "&$D8) -> 43-C2-C20_C2 - Marco | J8: 1 | K8: =IF($F8="","",($F8+'Base de Datos'!$B$2)/10) -> 18.5194 | L8: =IF($G8="","",($G8+'Base de Datos'!$B$2)/10) -> 102.8662 | M8: =IF($H8="","",($H8+'Base de Datos'!$B$2)/10) -> 307.74082
A9: FIJO MODULAR 3 | B9: Picture Window | C9: 16-C4 | D9: =IF($B9="","",IFERROR(INDEX('Base de Datos'!$B$6:$B$103,MATCH($B9,'Base de Datos'!$J$6:$J$103,0)),"No encontrado")) -> Marco | E9: Marcos | F9: =IF($B9="","",IFERROR(INDEX('Base de Datos'!$C$6:$C$103,MATCH($B9,'Base de Datos'!$J$6:$J$103,0)),"")) -> 80.01 | G9: 901.7 | H9: 609.6 | I9: =IF(AND($C9="",$D9=""),"",$C9&" - "&$D9) -> 16-C4 - Marco | J9: 2 | K9: =IF($F9="","",($F9+'Base de Datos'!$B$2)/10) -> 11.001 | L9: =IF($G9="","",($G9+'Base de Datos'!$B$2)/10) -> 93.17 | M9: =IF($H9="","",($H9+'Base de Datos'!$B$2)/10) -> 63.96
A10: FIJO MODULAR 3 | B10: Picture Window | C10: 47-A1 | D10: =IF($B10="","",IFERROR(INDEX('Base de Datos'!$B$6:$B$103,MATCH($B10,'Base de Datos'!$J$6:$J$103,0)),"No encontrado")) -> Marco | E10: Marcos | F10: =IF($B10="","",IFERROR(INDEX('Base de Datos'!$C$6:$C$103,MATCH($B10,'Base de Datos'!$J$6:$J$103,0)),"")) -> 80.01 | G10: 736.6 | H10: 1193.8 | I10: =IF(AND($C10="",$D10=""),"",$C10&" - "&$D10) -> 47-A1 - Marco | J10: 1 | K10: =IF($F10="","",($F10+'Base de Datos'!$B$2)/10) -> 11.001 | L10: =IF($G10="","",($G10+'Base de Datos'!$B$2)/10) -> 76.66 | M10: =IF($H10="","",($H10+'Base de Datos'!$B$2)/10) -> 122.38
A11: KA SGD | B11: Sliding glass - Hoja Activa | C11: 58-013 | D11: =IF($B11="","",IFERROR(INDEX('Base de Datos'!$B$6:$B$103,MATCH($B11,'Base de Datos'!$J$6:$J$103,0)),"No encontrado")) -> Hoja Activa | E11: Hojas | F11: =IF($B11="","",IFERROR(INDEX('Base de Datos'!$C$6:$C$103,MATCH($B11,'Base de Datos'!$J$6:$J$103,0)),"")) -> 152.146 | G11: 1142.2072 | H11: 2405.2001 | I11: =IF(AND($C11="",$D11=""),"",$C11&" - "&$D11) -> 58-013 - Hoja Activa | J11: 1 | K11: =IF($F11="","",($F11+'Base de Datos'!$B$2)/10) -> 18.2146 | L11: =IF($G11="","",($G11+'Base de Datos'!$B$2)/10) -> 117.22072 | M11: =IF($H11="","",($H11+'Base de Datos'!$B$2)/10) -> 243.52001
A12: KA WINDOW WALL | B12: Window Wall | C12: 43-C2-C20_C2 | D12: =IF($B12="","",IFERROR(INDEX('Base de Datos'!$B$6:$B$103,MATCH($B12,'Base de Datos'!$J$6:$J$103,0)),"No encontrado")) -> Marco | E12: Marcos | F12: =IF($B12="","",IFERROR(INDEX('Base de Datos'!$C$6:$C$103,MATCH($B12,'Base de Datos'!$J$6:$J$103,0)),"")) -> 155.194 | G12: 758.2375 | H12: 3047.4082 | I12: =IF(AND($C12="",$D12=""),"",$C12&" - "&$D12) -> 43-C2-C20_C2 - Marco | J12: 1 | K12: =IF($F12="","",($F12+'Base de Datos'!$B$2)/10) -> 18.5194 | L12: =IF($G12="","",($G12+'Base de Datos'!$B$2)/10) -> 78.82375 | M12: =IF($H12="","",($H12+'Base de Datos'!$B$2)/10) -> 307.74082
A13: KA SGD | B13: Sliding glass - Hoja que recibe | C13: 58-013 | D13: =IF($B13="","",IFERROR(INDEX('Base de Datos'!$B$6:$B$103,MATCH($B13,'Base de Datos'!$J$6:$J$103,0)),"No encontrado")) -> Hoja que recibe | E13: Hojas | F13: =IF($B13="","",IFERROR(INDEX('Base de Datos'!$C$6:$C$103,MATCH($B13,'Base de Datos'!$J$6:$J$103,0)),"")) -> 94.996 | G13: 1142.2072 | H13: 2405.2001 | I13: =IF(AND($C13="",$D13=""),"",$C13&" - "&$D13) -> 58-013 - Hoja que recibe | J13: 1 | K13: =IF($F13="","",($F13+'Base de Datos'!$B$2)/10) -> 12.4996 | L13: =IF($G13="","",($G13+'Base de Datos'!$B$2)/10) -> 117.22072 | M13: =IF($H13="","",($H13+'Base de Datos'!$B$2)/10) -> 243.52001
A14: KA SGD | B14: Sliding glass - Hoja Activa | C14: 59-010 | D14: =IF($B14="","",IFERROR(INDEX('Base de Datos'!$B$6:$B$103,MATCH($B14,'Base de Datos'!$J$6:$J$103,0)),"No encontrado")) -> Hoja Activa | E14: Hojas | F14: =IF($B14="","",IFERROR(INDEX('Base de Datos'!$C$6:$C$103,MATCH($B14,'Base de Datos'!$J$6:$J$103,0)),"")) -> 152.146 | G14: 1432.86 | H14: 2405.2001 | I14: =IF(AND($C14="",$D14=""),"",$C14&" - "&$D14) -> 59-010 - Hoja Activa | J14: 1 | K14: =IF($F14="","",($F14+'Base de Datos'!$B$2)/10) -> 18.2146 | L14: =IF($G14="","",($G14+'Base de Datos'!$B$2)/10) -> 146.286 | M14: =IF($H14="","",($H14+'Base de Datos'!$B$2)/10) -> 243.52001
A15: FIJO MODULAR 3 | B15: Picture Window | C15: 32-C15 | D15: =IF($B15="","",IFERROR(INDEX('Base de Datos'!$B$6:$B$103,MATCH($B15,'Base de Datos'!$J$6:$J$103,0)),"No encontrado")) -> Marco | E15: Marcos | F15: =IF($B15="","",IFERROR(INDEX('Base de Datos'!$C$6:$C$103,MATCH($B15,'Base de Datos'!$J$6:$J$103,0)),"")) -> 80.01 | G15: 1651 | H15: 596.9 | I15: =IF(AND($C15="",$D15=""),"",$C15&" - "&$D15) -> 32-C15 - Marco | J15: 1 | K15: =IF($F15="","",($F15+'Base de Datos'!$B$2)/10) -> 11.001 | L15: =IF($G15="","",($G15+'Base de Datos'!$B$2)/10) -> 168.1 | M15: =IF($H15="","",($H15+'Base de Datos'!$B$2)/10) -> 62.69
... A102: KA SGD | B102: Sliding glass - Hoja fija | C102: 20-008 | D102: =IF($B102="","",IFERROR(INDEX('Base de Datos'!$B$6:$B$103,MATCH($B102,'Base de Datos'!$J$6:$J$103,0)),"No encontrado")) -> Hoja fija | E102: Hojas | F102: =IF($B102="","",IFERROR(INDEX('Base de Datos'!$C$6:$C$103,MATCH($B102,'Base de Datos'!$J$6:$J$103,0)),"")) -> 94.996 | G102: 1230.55 | H102: 3021.15 | I102: =IF(AND($C102="",$D102=""),"",$C102&" - "&$D102) -> 20-008 - Hoja fija | J102: 1 | K102: =IF($F102="","",($F102+'Base de Datos'!$B$2)/10) -> 12.4996 | L102: =IF($G102="","",($G102+'Base de Datos'!$B$2)/10) -> 126.055 | M102: =IF($H102="","",($H102+'Base de Datos'!$B$2)/10) -> 305.115
A103: KA SGD | B103: Sliding glass - Hoja Activa | C103: 22-009 | D103: Hoja Activa | E103: Hojas | F103: 152.5 | G103: 915 | H103: 3025.95 | I103: 22-009 - Hoja Activa | J103: 1 | K103: 18.25 | L103: 94.5 | M103: 305.595
A104: KA SGD | B104: Sliding glass - Hoja Activa | C104: 22-009 | D104: Hoja Activa | E104: Hojas | F104: 152.5 | G104: 915 | H104: 3025.95 | I104: 22-009 - Hoja Activa | J104: 1 | K104: 18.25 | L104: 94.5 | M104: 305.595
A105: KA SGD | B105: Sliding glass - Hoja Activa | C105: 52-014 | D105: Hoja Activa | E105: Hojas | F105: 152.5 | G105: 915 | H105: 2410.0001 | I105: 52-014 - Hoja Activa | J105: 1 | K105: 18.25 | L105: 94.5 | M105: 244.00001
A106: KA SGD | B106: Sliding glass - Hoja Activa | C106: 52-014 | D106: Hoja Activa | E106: Hojas | F106: 152.5 | G106: 915 | H106: 2410.0001 | I106: 52-014 - Hoja Activa | J106: 1 | K106: 18.25 | L106: 94.5 | M106: 244.00001
A107: KA SGD | B107: Sliding glass - Hoja fija | C107: 53-013 | D107: =IF($B107="","",IFERROR(INDEX('Base de Datos'!$B$6:$B$103,MATCH($B107,'Base de Datos'!$J$6:$J$103,0)),"No encontrado")) -> Hoja fija | E107: Hojas | F107: =IF($B107="","",IFERROR(INDEX('Base de Datos'!$C$6:$C$103,MATCH($B107,'Base de Datos'!$J$6:$J$103,0)),"")) -> 94.996 | G107: 1211.9 | H107: 2410.0001 | I107: =IF(AND($C107="",$D107=""),"",$C107&" - "&$D107) -> 53-013 - Hoja fija | J107: 1 | K107: =IF($F107="","",($F107+'Base de Datos'!$B$2)/10) -> 12.4996 | L107: =IF($G107="","",($G107+'Base de Datos'!$B$2)/10) -> 124.19 | M107: =IF($H107="","",($H107+'Base de Datos'!$B$2)/10) -> 244.00001
A108: KA SGD | B108: Sliding glass - Hoja fija | C108: 57-013 | D108: =IF($B108="","",IFERROR(INDEX('Base de Datos'!$B$6:$B$103,MATCH($B108,'Base de Datos'!$J$6:$J$103,0)),"No encontrado")) -> Hoja fija | E108: Hojas | F108: =IF($B108="","",IFERROR(INDEX('Base de Datos'!$C$6:$C$103,MATCH($B108,'Base de Datos'!$J$6:$J$103,0)),"")) -> 94.996 | G108: 1211.9 | H108: 2410.0001 | I108: =IF(AND($C108="",$D108=""),"",$C108&" - "&$D108) -> 57-013 - Hoja fija | J108: 1 | K108: =IF($F108="","",($F108+'Base de Datos'!$B$2)/10) -> 12.4996 | L108: =IF($G108="","",($G108+'Base de Datos'!$B$2)/10) -> 124.19 | M108: =IF($H108="","",($H108+'Base de Datos'!$B$2)/10) -> 244.00001
A109: KA SGD | B109: Sliding glass - Hoja fija | C109: 57-010 | D109: =IF($B109="","",IFERROR(INDEX('Base de Datos'!$B$6:$B$103,MATCH($B109,'Base de Datos'!$J$6:$J$103,0)),"No encontrado")) -> Hoja fija | E109: Hojas | F109: =IF($B109="","",IFERROR(INDEX('Base de Datos'!$C$6:$C$103,MATCH($B109,'Base de Datos'!$J$6:$J$103,0)),"")) -> 94.996 | G109: 1211.9 | H109: 2410.0001 | I109: =IF(AND($C109="",$D109=""),"",$C109&" - "&$D109) -> 57-010 - Hoja fija | J109: 1 | K109: =IF($F109="","",($F109+'Base de Datos'!$B$2)/10) -> 12.4996 | L109: =IF($G109="","",($G109+'Base de Datos'!$B$2)/10) -> 124.19 | M109: =IF($H109="","",($H109+'Base de Datos'!$B$2)/10) -> 244.00001
A110: KA SGD | B110: Sliding glass - Hoja Activa | C110: 57-010 | D110: =IF($B110="","",IFERROR(INDEX('Base de Datos'!$B$6:$B$103,MATCH($B110,'Base de Datos'!$J$6:$J$103,0)),"No encontrado")) -> Hoja Activa | E110: Hojas | F110: =IF($B110="","",IFERROR(INDEX('Base de Datos'!$C$6:$C$103,MATCH($B110,'Base de Datos'!$J$6:$J$103,0)),"")) -> 152.146 | G110: 1211.9 | H110: 2410.0001 | I110: =IF(AND($C110="",$D110=""),"",$C110&" - "&$D110) -> 57-010 - Hoja Activa | J110: 2 | K110: =IF($F110="","",($F110+'Base de Datos'!$B$2)/10) -> 18.2146 | L110: =IF($G110="","",($G110+'Base de Datos'!$B$2)/10) -> 124.19 | M110: =IF($H110="","",($H110+'Base de Datos'!$B$2)/10) -> 244.00001
A111: KA SGD | B111: Sliding glass - Hoja Activa | C111: 57-010 | D111: =IF($B111="","",IFERROR(INDEX('Base de Datos'!$B$6:$B$103,MATCH($B111,'Base de Datos'!$J$6:$J$103,0)),"No encontrado")) -> Hoja Activa | E111: Hojas | F111: =IF($B111="","",IFERROR(INDEX('Base de Datos'!$C$6:$C$103,MATCH($B111,'Base de Datos'!$J$6:$J$103,0)),"")) -> 152.146 | G111: 1211.9 | H111: 2410.0001 | I111: =IF(AND($C111="",$D111=""),"",$C111&" - "&$D111) -> 57-010 - Hoja Activa | J111: 3 | K111: =IF($F111="","",($F111+'Base de Datos'!$B$2)/10) -> 18.2146 | L111: =IF($G111="","",($G111+'Base de Datos'!$B$2)/10) -> 124.19 | M111: =IF($H111="","",($H111+'Base de Datos'!$B$2)/10) -> 244.00001
A112: KA SGD | B112: Sliding glass - Hoja que recibe | C112: 57-010 | D112: =IF($B112="","",IFERROR(INDEX('Base de Datos'!$B$6:$B$103,MATCH($B112,'Base de Datos'!$J$6:$J$103,0)),"No encontrado")) -> Hoja que recibe | E112: Hojas | F112: =IF($B112="","",IFERROR(INDEX('Base de Datos'!$C$6:$C$103,MATCH($B112,'Base de Datos'!$J$6:$J$103,0)),"")) -> 94.996 | G112: 1211.9 | H112: 2410.0001 | I112: =IF(AND($C112="",$D112=""),"",$C112&" - "&$D112) -> 57-010 - Hoja que recibe | J112: 4 | K112: =IF($F112="","",($F112+'Base de Datos'!$B$2)/10) -> 12.4996 | L112: =IF($G112="","",($G112+'Base de Datos'!$B$2)/10) -> 124.19 | M112: =IF($H112="","",($H112+'Base de Datos'!$B$2)/10) -> 244.00001
